#VRML_SIM R2025a utf8

EXTERNPROTO "https://raw.githubusercontent.com/cyberbotics/webots/R2025a/projects/objects/backgrounds/protos/TexturedBackground.proto"
EXTERNPROTO "https://raw.githubusercontent.com/cyberbotics/webots/R2025a/projects/objects/backgrounds/protos/TexturedBackgroundLight.proto"
EXTERNPROTO "https://raw.githubusercontent.com/cyberbotics/webots/R2025a/projects/objects/floors/protos/CircleArena.proto"

WorldInfo {
  title "Omniscience"
}
Viewpoint {
  orientation -0.25514264071172993 -0.010200555110016244 0.9668496168309177 3.2350583167908007
  position 2.6770247877527327 0.11281858696324515 1.7161213530661148
}
TexturedBackground {
}
TexturedBackgroundLight {
}
CircleArena {
}
DEF ROBOT1 Robot {
  translation 0.7128930250069729 0.45871695742905105 -0.00023231499317603876
  rotation 0.014354850025296904 -0.007360218234568475 0.9998698742677923 2.1465019812787873
  children [
    DEF MAIN_BODY Pose {
      translation 0 0 0.0415
      children [
        Shape {
          appearance PBRAppearance {
            baseColor 0.0820075 0.364731 0.8
            roughness 1
            metalness 0
          }
          geometry DEF BODY Cylinder {
            height 0.08
            radius 0.045
          }
        }
      ]
    }
    HingeJoint {
      jointParameters HingeJointParameters {
        position 81.58229443076584
        axis 0 1 0
        anchor 0 0 0.025
      }
      device [
        RotationalMotor {
          name "left wheel motor"
        }
        PositionSensor {
          name "left wheel sensor"
        }
      ]
      endPoint DEF LEFT_WHEEL Solid {
        translation 0 0.044999999999999984 0.025
        rotation 0 1 0 1.1994007446108035
        children [
          DEF WHEEL Pose {
            rotation -1 0 0 1.57
            children [
              Shape {
                appearance PBRAppearance {
                  baseColor 1 0 0
                  roughness 1
                  metalness 0
                }
                geometry Cylinder {
                  height 0.01
                  radius 0.025
                }
              }
            ]
          }
        ]
        name "left wheel"
        boundingObject DEF WHEEL Pose {
          rotation -1 0 0 1.57
          children [
            Shape {
              appearance PBRAppearance {
                baseColor 1 0 0
                roughness 1
                metalness 0
              }
              geometry Cylinder {
                height 0.01
                radius 0.025
              }
            }
          ]
        }
        physics DEF PHYSICS_WHEEL Physics {
          density -1
          mass 0.05
        }
        linearVelocity -0.0627900956505491 0.09771512372776725 1.4127347890664151e-06
        angularVelocity -3.875553995750887 -2.490668642218174 0.20886848717553358
      }
    }
    HingeJoint {
      jointParameters HingeJointParameters {
        position 92.22409721034194
        axis 0 1 0
        anchor 0 0 0.025
      }
      device [
        RotationalMotor {
          name "right wheel motor"
        }
        PositionSensor {
          name "right wheel sensor"
        }
      ]
      endPoint DEF RIGHT_WHEEL Solid {
        translation 0 -0.044999999999999984 0.025
        rotation 0 -1 0 0.3278470901722717
        children [
          DEF WHEEL Pose {
            rotation -1 0 0 1.57
            children [
              Shape {
                appearance PBRAppearance {
                  baseColor 1 0 0
                  roughness 1
                  metalness 0
                }
                geometry Cylinder {
                  height 0.01
                  radius 0.025
                }
              }
            ]
          }
        ]
        name "right wheel"
        boundingObject USE WHEEL
        physics DEF PHYSICS_WHEEL Physics {
          density -1
          mass 0.05
        }
        linearVelocity -0.0723990107340023 0.11266040099354682 -1.346221868125839e-06
        angularVelocity -4.538030917236507 -2.9160350200767007 0.21108512607764324
      }
    }
    DEF LEFT_EYE DistanceSensor {
      translation 0.042 0.02 0.063
      rotation 0 0 -1 -0.499205
      children [
        DEF INFRARED Pose {
          rotation 0.577656895078166 0.5771968951617173 -0.5771968951617173 -2.093935
          children [
            Shape {
              appearance PBRAppearance {
                baseColor 0.975691 0.981481 0.0252992
                roughness 1
                metalness 0
              }
              geometry Cylinder {
                height 0.004
                radius 0.008
              }
            }
          ]
        }
      ]
      name "ds0"
      lookupTable [
        0 1024 0
        0.05 1024 0
        0.15 0 0
      ]
      numberOfRays 2
      aperture 1
    }
    DEF RIGHT_EYE DistanceSensor {
      translation 0.042 -0.02 0.063
      rotation 0 0 1 -0.500795
      children [
        DEF INFRARED Pose {
          rotation 0.577656895078166 0.5771968951617173 -0.5771968951617173 -2.093935
          children [
            Shape {
              appearance PBRAppearance {
                baseColor 0.975691 0.981481 0.0252992
                roughness 1
                metalness 0
              }
              geometry Cylinder {
                height 0.004
                radius 0.008
              }
            }
          ]
        }
      ]
      name "ds1"
      lookupTable [
        0 1024 0
        0.05 1024 0
        0.15 0 0
      ]
      numberOfRays 2
      aperture 1
    }
    Receiver {
    }
    Camera {
      translation 0.045 0 0.045
      children [
        Pose {
          rotation 0 -1 0 1.57
          children [
            Shape {
              appearance PBRAppearance {
                baseColor 0.8 0.8 0.8
                roughness 1
                metalness 0
              }
              geometry Cylinder {
                height 0.01
                radius 0.007
              }
            }
          ]
        }
      ]
    }
  ]
  name "robot1"
  boundingObject DEF MYBOT_BOUNDING Pose {
    translation 0 0 0.0415
    children [
      DEF BODY Cylinder {
        height 0.08
        radius 0.045
      }
    ]
  }
  physics DEF MYBOT_PHYSICS Physics {
    density -1
    mass 0.5
  }
  controller "pyplayback"
  linearVelocity -0.06751100869663551 0.1052758152663758 -2.183998573206304e-05
  angularVelocity -0.0012697784940443881 0.0010256341613092141 0.20023213584217237
}
Robot {
  children [
    Emitter {
    }
  ]
  name "Driver"
  supervisor TRUE
}
